INFO:werkzeug: * Running on http://0.0.0.0:3111/ (Press CTRL+C to quit)
INFO:app:Metrics request successfull
INFO:werkzeug:127.0.0.1 - - [15/Nov/2021 13:50:50] "[37mGET /metrics HTTP/1.1[0m" 200 -
INFO:werkzeug:127.0.0.1 - - [15/Nov/2021 13:50:56] "[33mGET /healthz HTTP/1.1[0m" 404 -
INFO:werkzeug: * Running on http://0.0.0.0:3111/ (Press CTRL+C to quit)
INFO:app:Metrics request successfull
INFO:werkzeug:127.0.0.1 - - [15/Nov/2021 13:51:34] "[37mGET /healthz HTTP/1.1[0m" 200 -
INFO:werkzeug: * Running on http://0.0.0.0:3111/ (Press CTRL+C to quit)
INFO:app:Metrics request successfull
INFO:werkzeug:127.0.0.1 - - [15/Nov/2021 14:00:29] "[37mGET /healthz HTTP/1.1[0m" 200 -
INFO:app:Metrics request successfull
INFO:werkzeug:127.0.0.1 - - [15/Nov/2021 14:00:30] "[37mGET /healthz HTTP/1.1[0m" 200 -
INFO:werkzeug:127.0.0.1 - - [15/Nov/2021 14:00:34] "[37mGET / HTTP/1.1[0m" 200 -
INFO:werkzeug:127.0.0.1 - - [15/Nov/2021 14:00:36] "[37mGET /1 HTTP/1.1[0m" 200 -
ERROR:app:Exception on /create [GET]
Traceback (most recent call last):
  File "C:\Users\CDL\anaconda3\lib\site-packages\flask\app.py", line 2447, in wsgi_app
    response = self.full_dispatch_request()
  File "C:\Users\CDL\anaconda3\lib\site-packages\flask\app.py", line 1952, in full_dispatch_request
    rv = self.handle_user_exception(e)
  File "C:\Users\CDL\anaconda3\lib\site-packages\flask\app.py", line 1821, in handle_user_exception
    reraise(exc_type, exc_value, tb)
  File "C:\Users\CDL\anaconda3\lib\site-packages\flask\_compat.py", line 39, in reraise
    raise value
  File "C:\Users\CDL\anaconda3\lib\site-packages\flask\app.py", line 1950, in full_dispatch_request
    rv = self.dispatch_request()
  File "C:\Users\CDL\anaconda3\lib\site-packages\flask\app.py", line 1936, in dispatch_request
    return self.view_functions[rule.endpoint](**req.view_args)
  File "app.py", line 99, in create
    app.logger.info('Article' + title + 'created successfull')
UnboundLocalError: local variable 'title' referenced before assignment
INFO:werkzeug:127.0.0.1 - - [15/Nov/2021 14:00:37] "[35m[1mGET /create HTTP/1.1[0m" 500 -
INFO:app:Main request successfull
INFO:werkzeug:127.0.0.1 - - [15/Nov/2021 14:00:43] "[37mGET /about HTTP/1.1[0m" 200 -
ERROR:app:Exception on /create [GET]
Traceback (most recent call last):
  File "C:\Users\CDL\anaconda3\lib\site-packages\flask\app.py", line 2447, in wsgi_app
    response = self.full_dispatch_request()
  File "C:\Users\CDL\anaconda3\lib\site-packages\flask\app.py", line 1952, in full_dispatch_request
    rv = self.handle_user_exception(e)
  File "C:\Users\CDL\anaconda3\lib\site-packages\flask\app.py", line 1821, in handle_user_exception
    reraise(exc_type, exc_value, tb)
  File "C:\Users\CDL\anaconda3\lib\site-packages\flask\_compat.py", line 39, in reraise
    raise value
  File "C:\Users\CDL\anaconda3\lib\site-packages\flask\app.py", line 1950, in full_dispatch_request
    rv = self.dispatch_request()
  File "C:\Users\CDL\anaconda3\lib\site-packages\flask\app.py", line 1936, in dispatch_request
    return self.view_functions[rule.endpoint](**req.view_args)
  File "app.py", line 99, in create
    app.logger.info('Article' + title + 'created successfull')
UnboundLocalError: local variable 'title' referenced before assignment
INFO:werkzeug:127.0.0.1 - - [15/Nov/2021 14:00:44] "[35m[1mGET /create HTTP/1.1[0m" 500 -
INFO:werkzeug: * Running on http://0.0.0.0:3111/ (Press CTRL+C to quit)
INFO:werkzeug:127.0.0.1 - - [15/Nov/2021 14:15:24] "[37mGET /create HTTP/1.1[0m" 200 -
INFO:app:Article TITLE created successfull
INFO:werkzeug:127.0.0.1 - - [15/Nov/2021 14:15:52] "[32mPOST /create HTTP/1.1[0m" 302 -
INFO:werkzeug:127.0.0.1 - - [15/Nov/2021 14:15:52] "[37mGET / HTTP/1.1[0m" 200 -
INFO:werkzeug:127.0.0.1 - - [15/Nov/2021 14:15:55] "[37mGET /7 HTTP/1.1[0m" 200 -
INFO:werkzeug: * Running on http://0.0.0.0:3111/ (Press CTRL+C to quit)
INFO:werkzeug:127.0.0.1 - - [15/Nov/2021 14:16:52] "[37mGET / HTTP/1.1[0m" 200 -
INFO:werkzeug:127.0.0.1 - - [15/Nov/2021 14:16:54] "[37mGET /create HTTP/1.1[0m" 200 -
INFO:app:Article TITLE created successfull
INFO:werkzeug:127.0.0.1 - - [15/Nov/2021 14:17:10] "[32mPOST /create HTTP/1.1[0m" 302 -
INFO:werkzeug:127.0.0.1 - - [15/Nov/2021 14:17:10] "[37mGET / HTTP/1.1[0m" 200 -
INFO:werkzeug:127.0.0.1 - - [15/Nov/2021 14:17:12] "[37mGET /3 HTTP/1.1[0m" 200 -
INFO:app:Status request successfull
INFO:werkzeug:127.0.0.1 - - [15/Nov/2021 14:17:17] "[37mGET /healthz HTTP/1.1[0m" 200 -
INFO:app:Metrics request successfull
INFO:werkzeug:127.0.0.1 - - [15/Nov/2021 14:17:21] "[37mGET /metrics HTTP/1.1[0m" 200 -
INFO:werkzeug: * Running on http://0.0.0.0:3111/ (Press CTRL+C to quit)
INFO:werkzeug:127.0.0.1 - - [15/Nov/2021 15:03:03] "[37mGET /create HTTP/1.1[0m" 200 -
INFO:app:Article three created successfull
INFO:werkzeug:127.0.0.1 - - [15/Nov/2021 15:03:14] "[32mPOST /create HTTP/1.1[0m" 302 -
INFO:werkzeug:127.0.0.1 - - [15/Nov/2021 15:03:14] "[37mGET / HTTP/1.1[0m" 200 -
INFO:app:Metrics request successfull
INFO:werkzeug:127.0.0.1 - - [15/Nov/2021 15:04:00] "[37mGET /metrics HTTP/1.1[0m" 200 -
INFO:werkzeug: * Running on http://0.0.0.0:3111/ (Press CTRL+C to quit)
ERROR:app:Exception on /metrics [GET]
Traceback (most recent call last):
  File "C:\Users\CDL\anaconda3\lib\site-packages\flask\app.py", line 2447, in wsgi_app
    response = self.full_dispatch_request()
  File "C:\Users\CDL\anaconda3\lib\site-packages\flask\app.py", line 1952, in full_dispatch_request
    rv = self.handle_user_exception(e)
  File "C:\Users\CDL\anaconda3\lib\site-packages\flask\app.py", line 1821, in handle_user_exception
    reraise(exc_type, exc_value, tb)
  File "C:\Users\CDL\anaconda3\lib\site-packages\flask\_compat.py", line 39, in reraise
    raise value
  File "C:\Users\CDL\anaconda3\lib\site-packages\flask\app.py", line 1950, in full_dispatch_request
    rv = self.dispatch_request()
  File "C:\Users\CDL\anaconda3\lib\site-packages\flask\app.py", line 1936, in dispatch_request
    return self.view_functions[rule.endpoint](**req.view_args)
  File "app.py", line 44, in metrics
    postsCount = count(connection.execute('SELECT * FROM posts').fetchall())
NameError: name 'count' is not defined
INFO:werkzeug:127.0.0.1 - - [15/Nov/2021 15:53:01] "[35m[1mGET /metrics HTTP/1.1[0m" 500 -
INFO:werkzeug: * Running on http://0.0.0.0:3111/ (Press CTRL+C to quit)
ERROR:app:Exception on /metrics [GET]
Traceback (most recent call last):
  File "C:\Users\CDL\anaconda3\lib\site-packages\flask\app.py", line 2447, in wsgi_app
    response = self.full_dispatch_request()
  File "C:\Users\CDL\anaconda3\lib\site-packages\flask\app.py", line 1952, in full_dispatch_request
    rv = self.handle_user_exception(e)
  File "C:\Users\CDL\anaconda3\lib\site-packages\flask\app.py", line 1821, in handle_user_exception
    reraise(exc_type, exc_value, tb)
  File "C:\Users\CDL\anaconda3\lib\site-packages\flask\_compat.py", line 39, in reraise
    raise value
  File "C:\Users\CDL\anaconda3\lib\site-packages\flask\app.py", line 1950, in full_dispatch_request
    rv = self.dispatch_request()
  File "C:\Users\CDL\anaconda3\lib\site-packages\flask\app.py", line 1936, in dispatch_request
    return self.view_functions[rule.endpoint](**req.view_args)
  File "app.py", line 49, in metrics
    response=json.dumps({"status":"success","code":0,"data":{"db_connection_count":0,"post_count":postsCount}}),
  File "C:\Users\CDL\anaconda3\lib\site-packages\flask\json\__init__.py", line 211, in dumps
    rv = _json.dumps(obj, **kwargs)
  File "C:\Users\CDL\anaconda3\lib\json\__init__.py", line 234, in dumps
    return cls(
  File "C:\Users\CDL\anaconda3\lib\json\encoder.py", line 199, in encode
    chunks = self.iterencode(o, _one_shot=True)
  File "C:\Users\CDL\anaconda3\lib\json\encoder.py", line 257, in iterencode
    return _iterencode(o, 0)
  File "C:\Users\CDL\anaconda3\lib\site-packages\flask\json\__init__.py", line 100, in default
    return _json.JSONEncoder.default(self, o)
  File "C:\Users\CDL\anaconda3\lib\json\encoder.py", line 179, in default
    raise TypeError(f'Object of type {o.__class__.__name__} '
TypeError: Object of type Row is not JSON serializable
INFO:werkzeug:127.0.0.1 - - [15/Nov/2021 15:55:32] "[35m[1mGET /metrics HTTP/1.1[0m" 500 -
ERROR:app:Exception on /metrics [GET]
Traceback (most recent call last):
  File "C:\Users\CDL\anaconda3\lib\site-packages\flask\app.py", line 2447, in wsgi_app
    response = self.full_dispatch_request()
  File "C:\Users\CDL\anaconda3\lib\site-packages\flask\app.py", line 1952, in full_dispatch_request
    rv = self.handle_user_exception(e)
  File "C:\Users\CDL\anaconda3\lib\site-packages\flask\app.py", line 1821, in handle_user_exception
    reraise(exc_type, exc_value, tb)
  File "C:\Users\CDL\anaconda3\lib\site-packages\flask\_compat.py", line 39, in reraise
    raise value
  File "C:\Users\CDL\anaconda3\lib\site-packages\flask\app.py", line 1950, in full_dispatch_request
    rv = self.dispatch_request()
  File "C:\Users\CDL\anaconda3\lib\site-packages\flask\app.py", line 1936, in dispatch_request
    return self.view_functions[rule.endpoint](**req.view_args)
  File "app.py", line 49, in metrics
    response=json.dumps({"status":"success","code":0,"data":{"db_connection_count":0,"post_count":postsCount}}),
  File "C:\Users\CDL\anaconda3\lib\site-packages\flask\json\__init__.py", line 211, in dumps
    rv = _json.dumps(obj, **kwargs)
  File "C:\Users\CDL\anaconda3\lib\json\__init__.py", line 234, in dumps
    return cls(
  File "C:\Users\CDL\anaconda3\lib\json\encoder.py", line 199, in encode
    chunks = self.iterencode(o, _one_shot=True)
  File "C:\Users\CDL\anaconda3\lib\json\encoder.py", line 257, in iterencode
    return _iterencode(o, 0)
  File "C:\Users\CDL\anaconda3\lib\site-packages\flask\json\__init__.py", line 100, in default
    return _json.JSONEncoder.default(self, o)
  File "C:\Users\CDL\anaconda3\lib\json\encoder.py", line 179, in default
    raise TypeError(f'Object of type {o.__class__.__name__} '
TypeError: Object of type Row is not JSON serializable
INFO:werkzeug:127.0.0.1 - - [15/Nov/2021 15:55:34] "[35m[1mGET /metrics HTTP/1.1[0m" 500 -
INFO:werkzeug: * Running on http://0.0.0.0:3111/ (Press CTRL+C to quit)
ERROR:app:Exception on /metrics [GET]
Traceback (most recent call last):
  File "C:\Users\CDL\anaconda3\lib\site-packages\flask\app.py", line 2447, in wsgi_app
    response = self.full_dispatch_request()
  File "C:\Users\CDL\anaconda3\lib\site-packages\flask\app.py", line 1952, in full_dispatch_request
    rv = self.handle_user_exception(e)
  File "C:\Users\CDL\anaconda3\lib\site-packages\flask\app.py", line 1821, in handle_user_exception
    reraise(exc_type, exc_value, tb)
  File "C:\Users\CDL\anaconda3\lib\site-packages\flask\_compat.py", line 39, in reraise
    raise value
  File "C:\Users\CDL\anaconda3\lib\site-packages\flask\app.py", line 1950, in full_dispatch_request
    rv = self.dispatch_request()
  File "C:\Users\CDL\anaconda3\lib\site-packages\flask\app.py", line 1936, in dispatch_request
    return self.view_functions[rule.endpoint](**req.view_args)
  File "app.py", line 49, in metrics
    response=json.dumps({"status":"success","code":0,"data":{"db_connection_count":0,"post_count":postsCount}}),
  File "C:\Users\CDL\anaconda3\lib\site-packages\flask\json\__init__.py", line 211, in dumps
    rv = _json.dumps(obj, **kwargs)
  File "C:\Users\CDL\anaconda3\lib\json\__init__.py", line 234, in dumps
    return cls(
  File "C:\Users\CDL\anaconda3\lib\json\encoder.py", line 199, in encode
    chunks = self.iterencode(o, _one_shot=True)
  File "C:\Users\CDL\anaconda3\lib\json\encoder.py", line 257, in iterencode
    return _iterencode(o, 0)
  File "C:\Users\CDL\anaconda3\lib\site-packages\flask\json\__init__.py", line 100, in default
    return _json.JSONEncoder.default(self, o)
  File "C:\Users\CDL\anaconda3\lib\json\encoder.py", line 179, in default
    raise TypeError(f'Object of type {o.__class__.__name__} '
TypeError: Object of type Cursor is not JSON serializable
INFO:werkzeug:127.0.0.1 - - [15/Nov/2021 16:11:57] "[35m[1mGET /metrics HTTP/1.1[0m" 500 -
INFO:werkzeug: * Running on http://0.0.0.0:3111/ (Press CTRL+C to quit)
INFO:app:Metrics request successfull
INFO:werkzeug:127.0.0.1 - - [15/Nov/2021 20:42:54] "[37mGET /metrics HTTP/1.1[0m" 200 -
INFO:werkzeug:127.0.0.1 - - [15/Nov/2021 20:44:50] "[37mGET / HTTP/1.1[0m" 200 -
INFO:werkzeug:127.0.0.1 - - [15/Nov/2021 20:44:50] "[37mGET /static/css/main.css HTTP/1.1[0m" 200 -
INFO:werkzeug:127.0.0.1 - - [15/Nov/2021 20:44:52] "[37mGET /5 HTTP/1.1[0m" 200 -
INFO:werkzeug: * Running on http://0.0.0.0:3111/ (Press CTRL+C to quit)
ERROR:app:Exception on /8 [GET]
Traceback (most recent call last):
  File "C:\Users\CDL\anaconda3\lib\site-packages\flask\app.py", line 2447, in wsgi_app
    response = self.full_dispatch_request()
  File "C:\Users\CDL\anaconda3\lib\site-packages\flask\app.py", line 1952, in full_dispatch_request
    rv = self.handle_user_exception(e)
  File "C:\Users\CDL\anaconda3\lib\site-packages\flask\app.py", line 1821, in handle_user_exception
    reraise(exc_type, exc_value, tb)
  File "C:\Users\CDL\anaconda3\lib\site-packages\flask\_compat.py", line 39, in reraise
    raise value
  File "C:\Users\CDL\anaconda3\lib\site-packages\flask\app.py", line 1950, in full_dispatch_request
    rv = self.dispatch_request()
  File "C:\Users\CDL\anaconda3\lib\site-packages\flask\app.py", line 1936, in dispatch_request
    return self.view_functions[rule.endpoint](**req.view_args)
  File "app.py", line 77, in post
    post = get_post(post_id)
  File "app.py", line 23, in get_post
    app.logger.info('Article ' + title + ' fetched successfull')
TypeError: can only concatenate str (not "sqlite3.Row") to str
INFO:werkzeug:127.0.0.1 - - [15/Nov/2021 21:02:14] "[35m[1mGET /8 HTTP/1.1[0m" 500 -
INFO:werkzeug: * Running on http://0.0.0.0:3111/ (Press CTRL+C to quit)
INFO:werkzeug:127.0.0.1 - - [15/Nov/2021 21:07:41] "[37mGET /8 HTTP/1.1[0m" 200 -
INFO:werkzeug: * Running on http://0.0.0.0:3111/ (Press CTRL+C to quit)
INFO:werkzeug:127.0.0.1 - - [15/Nov/2021 21:09:51] "[37mGET /create HTTP/1.1[0m" 200 -
INFO:app:Article fffffive created successfull
INFO:werkzeug:127.0.0.1 - - [15/Nov/2021 21:09:59] "[32mPOST /create HTTP/1.1[0m" 302 -
INFO:werkzeug:127.0.0.1 - - [15/Nov/2021 21:09:59] "[37mGET / HTTP/1.1[0m" 200 -
INFO:werkzeug: * Running on http://0.0.0.0:3111/ (Press CTRL+C to quit)
INFO:werkzeug:127.0.0.1 - - [15/Nov/2021 21:10:45] "[37mGET /6 HTTP/1.1[0m" 200 -
INFO:werkzeug: * Running on http://0.0.0.0:3111/ (Press CTRL+C to quit)
INFO:werkzeug:127.0.0.1 - - [15/Nov/2021 21:12:16] "[37mGET /3 HTTP/1.1[0m" 200 -
INFO:werkzeug: * Running on http://0.0.0.0:3111/ (Press CTRL+C to quit)
INFO:app:Article Kubernetes v1.20 Release Notes fetched successfull
INFO:werkzeug:127.0.0.1 - - [15/Nov/2021 21:13:06] "[37mGET /3 HTTP/1.1[0m" 200 -
